2018-08-27 12:02:47,903 ERROR: Exception on /user/john [GET] [in /Users/Ian/anaconda3/lib/python3.6/site-packages/flask/app.py:1560]
Traceback (most recent call last):
  File "/Users/Ian/anaconda3/lib/python3.6/site-packages/flask/app.py", line 1982, in wsgi_app
    response = self.full_dispatch_request()
  File "/Users/Ian/anaconda3/lib/python3.6/site-packages/flask/app.py", line 1614, in full_dispatch_request
    rv = self.handle_user_exception(e)
  File "/Users/Ian/anaconda3/lib/python3.6/site-packages/flask/app.py", line 1517, in handle_user_exception
    reraise(exc_type, exc_value, tb)
  File "/Users/Ian/anaconda3/lib/python3.6/site-packages/flask/_compat.py", line 33, in reraise
    raise value
  File "/Users/Ian/anaconda3/lib/python3.6/site-packages/flask/app.py", line 1612, in full_dispatch_request
    rv = self.dispatch_request()
  File "/Users/Ian/anaconda3/lib/python3.6/site-packages/flask/app.py", line 1598, in dispatch_request
    return self.view_functions[rule.endpoint](**req.view_args)
  File "/Users/Ian/anaconda3/lib/python3.6/site-packages/flask_login/utils.py", line 261, in decorated_view
    return func(*args, **kwargs)
  File "/Users/Ian/PROJECTS/tut/app/routes.py", line 76, in user
    return render_template('user.html', user=user, posts=posts)
NameError: name 'posts' is not defined
2018-08-27 12:04:12,377 INFO: Microblog startup [in /Users/Ian/PROJECTS/tut/app/__init__.py:47]
2018-08-27 12:11:56,582 INFO: Microblog startup [in /Users/Ian/PROJECTS/tut/app/__init__.py:47]
2018-08-27 12:14:16,813 INFO: Microblog startup [in /Users/Ian/PROJECTS/tut/app/__init__.py:47]
2018-08-27 12:18:07,878 INFO: Microblog startup [in /Users/Ian/PROJECTS/tut/app/__init__.py:47]
2018-08-27 12:19:37,318 INFO: Microblog startup [in /Users/Ian/PROJECTS/tut/app/__init__.py:47]
2018-08-27 12:22:41,915 INFO: Microblog startup [in /Users/Ian/PROJECTS/tut/app/__init__.py:47]
2018-08-27 12:29:50,377 INFO: Microblog startup [in /Users/Ian/PROJECTS/tut/app/__init__.py:49]
2018-08-27 12:32:01,932 INFO: Microblog startup [in /Users/Ian/PROJECTS/tut/app/__init__.py:49]
2018-08-27 12:33:51,290 INFO: Microblog startup [in /Users/Ian/PROJECTS/tut/app/__init__.py:49]
2018-08-27 12:40:09,564 INFO: Microblog startup [in /Users/Ian/PROJECTS/tut/app/__init__.py:49]
2018-08-27 12:40:22,667 ERROR: Exception on /login [GET] [in /Users/Ian/anaconda3/lib/python3.6/site-packages/flask/app.py:1560]
Traceback (most recent call last):
  File "/Users/Ian/anaconda3/lib/python3.6/site-packages/flask/app.py", line 1982, in wsgi_app
    response = self.full_dispatch_request()
  File "/Users/Ian/anaconda3/lib/python3.6/site-packages/flask/app.py", line 1614, in full_dispatch_request
    rv = self.handle_user_exception(e)
  File "/Users/Ian/anaconda3/lib/python3.6/site-packages/flask/app.py", line 1517, in handle_user_exception
    reraise(exc_type, exc_value, tb)
  File "/Users/Ian/anaconda3/lib/python3.6/site-packages/flask/_compat.py", line 33, in reraise
    raise value
  File "/Users/Ian/anaconda3/lib/python3.6/site-packages/flask/app.py", line 1612, in full_dispatch_request
    rv = self.dispatch_request()
  File "/Users/Ian/anaconda3/lib/python3.6/site-packages/flask/app.py", line 1598, in dispatch_request
    return self.view_functions[rule.endpoint](**req.view_args)
  File "/Users/Ian/PROJECTS/tut/app/routes.py", line 54, in login
    return render_template('login.html', title='Sign In', form=form)
  File "/Users/Ian/anaconda3/lib/python3.6/site-packages/flask/templating.py", line 134, in render_template
    context, ctx.app)
  File "/Users/Ian/anaconda3/lib/python3.6/site-packages/flask/templating.py", line 116, in _render
    rv = template.render(context)
  File "/Users/Ian/anaconda3/lib/python3.6/site-packages/jinja2/asyncsupport.py", line 76, in render
    return original_render(self, *args, **kwargs)
  File "/Users/Ian/anaconda3/lib/python3.6/site-packages/jinja2/environment.py", line 1008, in render
    return self.environment.handle_exception(exc_info, True)
  File "/Users/Ian/anaconda3/lib/python3.6/site-packages/jinja2/environment.py", line 780, in handle_exception
    reraise(exc_type, exc_value, tb)
  File "/Users/Ian/anaconda3/lib/python3.6/site-packages/jinja2/_compat.py", line 37, in reraise
    raise value.with_traceback(tb)
  File "/Users/Ian/PROJECTS/tut/app/templates/login.html", line 1, in top-level template code
    {% extends "base.html" %}
  File "/Users/Ian/PROJECTS/tut/app/templates/base.html", line 32, in top-level template code
    {% block content %}{% endblock %}
  File "/Users/Ian/PROJECTS/tut/app/templates/login.html", line 27, in block "content"
    <a href="{{ url_for('reset_password_request') }}">Click to Reset It</a>
  File "/Users/Ian/anaconda3/lib/python3.6/site-packages/flask/helpers.py", line 333, in url_for
    return appctx.app.handle_url_build_error(error, endpoint, values)
  File "/Users/Ian/anaconda3/lib/python3.6/site-packages/flask/app.py", line 1805, in handle_url_build_error
    reraise(exc_type, exc_value, tb)
  File "/Users/Ian/anaconda3/lib/python3.6/site-packages/flask/_compat.py", line 33, in reraise
    raise value
  File "/Users/Ian/anaconda3/lib/python3.6/site-packages/flask/helpers.py", line 323, in url_for
    force_external=external)
  File "/Users/Ian/anaconda3/lib/python3.6/site-packages/werkzeug/routing.py", line 1768, in build
    raise BuildError(endpoint, values, method, self)
werkzeug.routing.BuildError: Could not build url for endpoint 'reset_password_request'. Did you mean 'edit_profile' instead?
2018-08-27 12:40:31,182 ERROR: Exception on /login [GET] [in /Users/Ian/anaconda3/lib/python3.6/site-packages/flask/app.py:1560]
Traceback (most recent call last):
  File "/Users/Ian/anaconda3/lib/python3.6/site-packages/flask/app.py", line 1982, in wsgi_app
    response = self.full_dispatch_request()
  File "/Users/Ian/anaconda3/lib/python3.6/site-packages/flask/app.py", line 1614, in full_dispatch_request
    rv = self.handle_user_exception(e)
  File "/Users/Ian/anaconda3/lib/python3.6/site-packages/flask/app.py", line 1517, in handle_user_exception
    reraise(exc_type, exc_value, tb)
  File "/Users/Ian/anaconda3/lib/python3.6/site-packages/flask/_compat.py", line 33, in reraise
    raise value
  File "/Users/Ian/anaconda3/lib/python3.6/site-packages/flask/app.py", line 1612, in full_dispatch_request
    rv = self.dispatch_request()
  File "/Users/Ian/anaconda3/lib/python3.6/site-packages/flask/app.py", line 1598, in dispatch_request
    return self.view_functions[rule.endpoint](**req.view_args)
  File "/Users/Ian/PROJECTS/tut/app/routes.py", line 54, in login
    return render_template('login.html', title='Sign In', form=form)
  File "/Users/Ian/anaconda3/lib/python3.6/site-packages/flask/templating.py", line 134, in render_template
    context, ctx.app)
  File "/Users/Ian/anaconda3/lib/python3.6/site-packages/flask/templating.py", line 116, in _render
    rv = template.render(context)
  File "/Users/Ian/anaconda3/lib/python3.6/site-packages/jinja2/asyncsupport.py", line 76, in render
    return original_render(self, *args, **kwargs)
  File "/Users/Ian/anaconda3/lib/python3.6/site-packages/jinja2/environment.py", line 1008, in render
    return self.environment.handle_exception(exc_info, True)
  File "/Users/Ian/anaconda3/lib/python3.6/site-packages/jinja2/environment.py", line 780, in handle_exception
    reraise(exc_type, exc_value, tb)
  File "/Users/Ian/anaconda3/lib/python3.6/site-packages/jinja2/_compat.py", line 37, in reraise
    raise value.with_traceback(tb)
  File "/Users/Ian/PROJECTS/tut/app/templates/login.html", line 1, in top-level template code
    {% extends "base.html" %}
  File "/Users/Ian/PROJECTS/tut/app/templates/base.html", line 32, in top-level template code
    {% block content %}{% endblock %}
  File "/Users/Ian/PROJECTS/tut/app/templates/login.html", line 27, in block "content"
    <a href="{{ url_for('reset_password_request') }}">Click to Reset It</a>
  File "/Users/Ian/anaconda3/lib/python3.6/site-packages/flask/helpers.py", line 333, in url_for
    return appctx.app.handle_url_build_error(error, endpoint, values)
  File "/Users/Ian/anaconda3/lib/python3.6/site-packages/flask/app.py", line 1805, in handle_url_build_error
    reraise(exc_type, exc_value, tb)
  File "/Users/Ian/anaconda3/lib/python3.6/site-packages/flask/_compat.py", line 33, in reraise
    raise value
  File "/Users/Ian/anaconda3/lib/python3.6/site-packages/flask/helpers.py", line 323, in url_for
    force_external=external)
  File "/Users/Ian/anaconda3/lib/python3.6/site-packages/werkzeug/routing.py", line 1768, in build
    raise BuildError(endpoint, values, method, self)
werkzeug.routing.BuildError: Could not build url for endpoint 'reset_password_request'. Did you mean 'edit_profile' instead?
2018-08-27 12:50:29,845 INFO: Microblog startup [in /Users/Ian/PROJECTS/tut/app/__init__.py:49]
2018-08-27 12:56:17,707 INFO: Microblog startup [in /Users/Ian/PROJECTS/tut/app/__init__.py:49]
2018-08-27 12:59:08,417 INFO: Microblog startup [in /Users/Ian/PROJECTS/tut/app/__init__.py:49]
2018-08-27 13:07:03,181 INFO: Microblog startup [in /Users/Ian/PROJECTS/tut/app/__init__.py:49]
2018-08-27 13:17:25,357 INFO: Microblog startup [in /Users/Ian/PROJECTS/tut/app/__init__.py:51]
2018-08-27 13:18:50,252 INFO: Microblog startup [in /Users/Ian/PROJECTS/tut/app/__init__.py:51]
2018-08-27 13:22:14,327 INFO: Microblog startup [in /Users/Ian/PROJECTS/tut/app/__init__.py:51]
2018-08-27 13:24:11,714 INFO: Microblog startup [in /Users/Ian/PROJECTS/tut/app/__init__.py:51]
2018-08-27 13:25:33,305 INFO: Microblog startup [in /Users/Ian/PROJECTS/tut/app/__init__.py:51]
2018-08-27 14:26:09,546 INFO: Microblog startup [in /Users/Ian/PROJECTS/tut/app/__init__.py:51]
2018-08-27 14:29:45,437 INFO: Microblog startup [in /Users/Ian/PROJECTS/tut/app/__init__.py:51]
2018-08-27 14:35:25,746 INFO: Microblog startup [in /Users/Ian/PROJECTS/tut/app/__init__.py:51]
2018-08-27 14:38:21,347 INFO: Microblog startup [in /Users/Ian/PROJECTS/tut/app/__init__.py:51]
2018-08-27 14:41:32,751 INFO: Microblog startup [in /Users/Ian/PROJECTS/tut/app/__init__.py:51]
2018-08-27 14:45:16,528 INFO: Microblog startup [in /Users/Ian/PROJECTS/tut/app/__init__.py:51]
